<?xml version="1.0"?>
<robot xmlns:xacro="http://www.ros.org/wiki/xacro" name="pod">
  <xacro:arg name="id" default="2" />
  <xacro:arg name="fixed" default="true" />
  <xacro:include filename="$(find tahoma_description)/robots/pod$(arg id).xacro"/>

  <xacro:if value="$(arg fixed)">
    <link name="world"/>
    <joint name="fixed" type="floating">
        <parent link="world"/>
        <child link="pod_base_link"/>
    </joint>
  </xacro:if>

  <gazebo reference="pod_base_link">
    <material>Gazebo/Gray</material>
  </gazebo>

  <xacro:macro name="color_pod_fabric" params="prefix">
    <xacro:arg name="prefix" default=""/>

    <xacro:property name="recipe_a" value="${[0,0,0,0,0,0,0,0]}"/>
    <xacro:property name="alphabet" value="abcdefghijklmnopqrstuvwxyz"/>

    <xacro:macro name="shifted_box" params="name">
      <gazebo reference="${name}">
        <material>AURMR/YellowFabric</material>
      </gazebo>
    </xacro:macro>

    <xacro:macro name="bin" params="prefix:=^ id">
      <xacro:property name="bin_name" value="${prefix}bin_${id}"/>

      <xacro:shifted_box name="${bin_name}_bottom" />
      <xacro:shifted_box name="${bin_name}_left"/>
      <xacro:shifted_box name="${bin_name}_right"/>
      <xacro:shifted_box name="${bin_name}_top" />
      <xacro:shifted_box name="${bin_name}_back" />
      <xacro:shifted_box name="${bin_name}_flap" />
    </xacro:macro>

    <xacro:macro name="bin_row" params="prefix:=^ id parent sections  i:=0">
      <xacro:bin prefix="${prefix}" id="${i+1}${id}" />
      <xacro:property name="bin_name" value="${prefix}bin_${i+1}${id}"/>

      <xacro:if value="${sections > 1}">
        <!-- recurse for the remaining bins -->
        <xacro:bin_row id="${id}" parent="${parent}" sections="${sections - 1}" i="${i + 1}"/>
      </xacro:if>
    </xacro:macro>

    <xacro:macro name="shelf" params="prefix:=^ sections:=3 id">
      <xacro:property name="shelf_name" value="${prefix}shelf_${id}"/>

      <xacro:bin_row id="${id}" parent="${shelf_name}" sections="${sections}"/>
    </xacro:macro>

    <xacro:macro name="shelf_stack" params="prefix:=^ parent recipe  i:=0">
      <xacro:property name="shelf_name" value="${prefix}shelf_${alphabet[i]}"/>
      <xacro:shelf prefix="${prefix}" id="${alphabet[i]}" />
      <xacro:if value="${len(recipe) > 1}">
        <!-- recurse -->
        <xacro:shelf_stack parent="${parent}" recipe="${recipe[1:]}" i="${i+1}"/>
      </xacro:if>
    </xacro:macro>

    <xacro:shelf_stack prefix="pod_" parent="${prefix}fabric_base" recipe="${recipe_a}"/>
  </xacro:macro>


  <xacro:color_pod_fabric prefix="pod_" />

</robot>